Workbook

Sheet 2023년최신
A1: variable | B1: variable description | C1: option description | D1: data type | E1: drop_col
A2: mod_d | B2: 최종 DB 수정일 | D2: object | E2: 0
A3: ID | B3: 개인 아이디 | D3: object | E3: 0
A4: ID_fam | B4: 가구 아이디 | D4: object | E4: 0
A5: year | B5: 조사연도 | D5: numeric | E5: 0
A6: region | B6: 17개 시도 | C6: 1: 서울 | 2: 부산 | 3: 대구 | 4: 인천 | 5: 광주 | 6: 대전 | 7: 울산 | 8: 세종 | 9: 경기 | 10: 강원 | 11: 충북 | 12: 충남 | 13: 전북 | 14: 전남 | 15: 경북 | 16: 경남 | 17: 제주 | D6: category | E6: 0
A7: town_t | B7: 동/읍면 구분 | C7: 1: 동 | 2: 읍·면 | D7: category | E7: 0
A8: apt_t | B8: 아파트 구분 | C8: 1: 일반 | 2: 아파트 | D8: category | E8: 0
A9: psu | B9: 조사구번호 | D9: object | E9: 0
A10: sex | B10: 성별 | C10: 1: 남자 | 2: 여자 | D10: category | E10: 0
A11: age | B11: 나이 | C11: 1~79: 실제 1~79세 | 80: 80세 이상 | D11: numeric_age | E11: 0
A12: age_month | B12: 월령(1~6세) | D12: numeric | E12: 0
A13: incm | B13: 소득 4분위수(개인) | C13: 1: 하 | 2: 중하 | 3: 중상 | 4: 상 | D13: category | E13: 0
A14: ho_incm | B14: 소득 4분위수(가구) | C14: 1: 하 | 2: 중하 | 3: 중상 | 4: 상 | D14: category | E14: 0
A15: incm5 | B15: 소득 5분위수(개인) | C15: 1: 하 | 2: 중하 | 3: 중 | 4: 중상 | 5: 상 | D15: category | E15: 0
A16: ho_incm5 | B16: 소득 5분위수(가구) | C16: 1: 하 | 2: 중하 | 3: 중 | 4: 중상 | 5: 상 | D16: category | E16: 0
A17: edu | B17: 교육수준 | C17: 1: 초졸이하 | 2: 중졸 | 3: 고졸 | 4: 대졸이상 | D17: category | E17: 0
A18: occp | B18: 직업재분류 | C18: 1: 관리자·전문가 | 2: 사무종사자 | 3: 서비스·판매 | 4: 농림어업 | 5: 기능·기계조작·조립 | 6: 단순노무 | 7: 무직(주부·학생 등) | D18: category | E18: 0
A19: wt_hs | B19: 가구조사 가중치 | D19: numeric | E19: 1
A20: wt_itvex | B20: 건강설문-검진조사 가중치 | D20: numeric | E20: 1
A21: wt_oe | B21: 구강검사 가중치 | D21: numeric | E21: 1
A22: wt_bia | B22: 체성분검사 가중치(10세 이상) | D22: numeric | E22: 1
A23: wt_ntr | B23: 영양조사 가중치 | D23: numeric | E23: 1
A24: wt_tot | B24: 건강설문·검진·영양조사 통합 가중치 | D24: numeric | E24: 1
A25: wt_oent | B25: 구강검사·영양조사 가중치 | D25: numeric | E25: 1
A26: wt_biant | B26: 체성분·영양조사 가중치(10세 이상) | D26: numeric | E26: 1
A27: kstrata | B27: 분산추정 층 | D27: numeric | E27: 1
A28: cfam | B28: 가구원수 | C28: 1: 1명 | 2: 2명 | 3: 3명 | 4: 4명 | 5: 5명 | 6: 6명 이상 | 9: 모름·무응답 | D28: category | E28: 0
A29: genertn | B29: 가구 세대구성코드 | C29: 1: 1세대-1인가구 | 2: 1세대-부부 | 3: 1세대-기타 | 4: 2세대-부부+미혼자녀 | 5: 2세대-편부모+미혼자녀 | 6: 2세대-기타 | 7: 3세대 이상 | 9: 모름·무응답 | D29: category | E29: 0
A30: allownc | B30: 기초생활수급 여부 | C30: 10: 수급경험 있음 | 20: 없음 | 99: 모름·무응답 | D30: category | E30: 0
A31: house | B31: 주택소유여부 | C31: 1: 아니오 | 2: 1채 있음 | 3: 2채 이상 있음 | 9: 모름·무응답 | D31: category | E31: 0
A32: live_t | B32: 주택형태 | C32: 1: 단독주택 | 2: 아파트 | 3: 연립·다세대 | 4: 기타 | 9: 모름·무응답 | D32: category | E32: 0
A33: ainc_unit1 | B33: 가구총소득 단위(개방형) | C33: 1: 연 | 2: 월 | 9: 모름·무응답 | D33: category | E33: 0
A34: ainc_1 | B34: 가구총소득 금액(개방형) | C34: 999999: 모름·무응답 | D34: numeric | E34: 0
A35: ainc | B35: 월평균 가구총소득 | C35: 17 이하 | 17초과~1500미만 | 1500 이상 | D35: numeric | E35: 0
A36: marri_1 | B36: 결혼여부 | C36: 1: 기혼 | 2: 미혼 | 9: 모름·무응답 | D36: category | E36: 0
A37: marri_2 | B37: 결혼상태 | C37: 1: 유배우자·동거 | 2: 유배우자·별거 | 3: 사별 | 4: 이혼 | 8: 응답거부 | 9: 모름 | 88: 비해당 | 99: 무응답 | D37: category | E37: 0
A38: fam_rela | B38: 가구주와의 관계 | C38: 1: 본인 | 2: 배우자 | 3: 자녀 | 4: 자녀배우자 | 5: 손자녀 | 6: 부모 | 7: 조부모 | 8: 형제자매 | 9: 기타친척 | 10: 비혈연 | 99: 모름·무응답 | D38: category | E38: 0
A39: tins | B39: 건강보험 종류 | C39: 10: 지역 | 20: 직장 | 30: 의료급여 | 99: 미가입·모름·무응답 | D39: category | E39: 0
A40: npins | B40: 민간의료보험 가입여부 | C40: 1: 예 | 2: 아니오 | 9: 모름·무응답 | D40: category | E40: 0
...

Sheet 국건영(지침서)_copy
A1: variable | B1: variable description | C1: option description | D1: data type | E1: drop_col
A2: mod_d | B2: 최종 DB 수정일 | D2: object | E2: 0 | F2: =VLOOKUP(A2,'2023년최신'!$A$2:$B$1000,2,FALSE) -> 최종 DB 수정일
A3: ID | B3: 개인 아이디 | D3: object | E3: 0 | F3: =VLOOKUP(A3,'2023년최신'!$A$2:$B$1000,2,FALSE) -> 개인 아이디
A4: ID_fam | B4: 개인 아이디 | D4: object | E4: 0 | F4: =VLOOKUP(A4,'2023년최신'!$A$2:$B$1000,2,FALSE) -> 가구 아이디
A5: year | B5: 조사연도 | D5: numeric | E5: 0 | F5: =VLOOKUP(A5,'2023년최신'!$A$2:$B$1000,2,FALSE) -> 조사연도
A6: region | B6: 16개 시도 | C6: 1 : 서울 | 2 : 부산 | 3 : 대구 | 4 : 인천 | 5 : 광주 | 6 : 대전 | 7 : 울산 | 8 : 세종 | 9 : 경기 | 10 : 강원 | 11 : 충북 | 12 : 충남 | 13 : 전북 | 14 : 전남 | 15 : 경북 | 16 : 경남 | 17 : 제주 | | D6: category | E6: 0 | F6: =VLOOKUP(A6,'2023년최신'!$A$2:$B$1000,2,FALSE) -> 17개 시도
A7: town_t | B7: 동/읍면 구분 | C7: 1 : 동 | 2 : 읍·면 | | D7: category | E7: 0 | F7: =VLOOKUP(A7,'2023년최신'!$A$2:$B$1000,2,FALSE) -> 동/읍면 구분
A8: apt_t | B8: 아파트 구분 | C8: 1 : 일반 | 2 : 아파트 | | D8: category | E8: 0 | F8: =VLOOKUP(A8,'2023년최신'!$A$2:$B$1000,2,FALSE) -> 아파트 구분
A9: psu | B9: 조사구번호 | D9: object | E9: 0 | F9: =VLOOKUP(A9,'2023년최신'!$A$2:$B$1000,2,FALSE) -> 조사구번호
A10: sex | B10: 성별 | C10: 1 : 남자 | 2 : 여자 | | D10: category | E10: 0 | F10: =VLOOKUP(A10,'2023년최신'!$A$2:$B$1000,2,FALSE) -> 성별
A11: age | B11: 만나이 | C11: 1~79 : 1~79세 | 80 : 80세이상 | | D11: numeric_age | E11: 0 | F11: =VLOOKUP(A11,'2023년최신'!$A$2:$B$1000,2,FALSE) -> 나이
A12: age_month | B12: 월령(개월,1~6세) | D12: numeric | E12: 0 | F12: =VLOOKUP(A12,'2023년최신'!$A$2:$B$1000,2,FALSE) -> 월령(1~6세)
A13: incm | B13: 소득 사분위수(개인) | C13: 1 : 하 | 2 : 중하 | 3 : 중상 | 4 : 상 | | D13: category | E13: 0 | F13: =VLOOKUP(A13,'2023년최신'!$A$2:$B$1000,2,FALSE) -> 소득 4분위수(개인)
A14: ho_incm | B14: 소득 사분위수(가구) | C14: 1 : 하 | 2 : 중하 | 3 : 중상 | 4 : 상 | | D14: category | E14: 0 | F14: =VLOOKUP(A14,'2023년최신'!$A$2:$B$1000,2,FALSE) -> 소득 4분위수(가구)
A15: incm5 | B15: 소득 오분위수(개인) | C15: 1 : 하 | 2 : 중하 | 3 : 중 | 4 : 중상 | 5 : 상 | | D15: category | E15: 0 | F15: =VLOOKUP(A15,'2023년최신'!$A$2:$B$1000,2,FALSE) -> 소득 5분위수(개인)
A16: ho_incm5 | B16: 소득 오분위수(가구) | C16: 1 : 하 | 2 : 중하 | 3 : 중 | 4 : 중상 | 5 : 상 | | D16: category | E16: 0 | F16: =VLOOKUP(A16,'2023년최신'!$A$2:$B$1000,2,FALSE) -> 소득 5분위수(가구)
A17: edu | B17: 교육수준 재분류 코드 | C17: 1 : 초졸이하 | 2 : 중졸 | 3 : 고졸 | 4 : 대졸이상 | | D17: category | E17: 0 | F17: =VLOOKUP(A17,'2023년최신'!$A$2:$B$1000,2,FALSE) -> 교육수준
A18: occp | B18: 직업재분류 및 실업/비경제활동 상태 코드 | C18: 1 : 관리자, 전문가 및 관련 종사자 | 2 : 사무종사자 | 3 : 서비스 및 판매 종사자 | 4 : 농림어업 숙련 종사자 | 5 : 기능원, 장치?기계조작 및 조립종사자 | 6 : 단순노무종사자 | 7 : 무직(주부, 학생 등) | | D18: category | E18: 0 | F18: =VLOOKUP(A18,'2023년최신'!$A$2:$B$1000,2,FALSE) -> 직업재분류
A19: wt_hs | B19: 가구조사 가중치 | D19: numeric | E19: 1 | F19: =VLOOKUP(A19,'2023년최신'!$A$2:$B$1000,2,FALSE) -> 가구조사 가중치
A20: wt_itvex | B20: 건강설문-검진조사 가중치 | D20: numeric | E20: 1 | F20: =VLOOKUP(A20,'2023년최신'!$A$2:$B$1000,2,FALSE) -> 건강설문-검진조사 가중치
A21: wt_oe | B21: 구강검사 가중치 | D21: numeric | E21: 1 | F21: =VLOOKUP(A21,'2023년최신'!$A$2:$B$1000,2,FALSE) -> 구강검사 가중치
A22: wt_bia | B22: 체성분검사 가중치(10세이상) | D22: numeric | E22: 1 | F22: =VLOOKUP(A22,'2023년최신'!$A$2:$B$1000,2,FALSE) -> 체성분검사 가중치(10세 이상)
A23: wt_ntr | B23: 영양조사 가중치 | D23: numeric | E23: 1 | F23: =VLOOKUP(A23,'2023년최신'!$A$2:$B$1000,2,FALSE) -> 영양조사 가중치
A24: wt_tot | B24: 건강설문-검진조사 & 영양조사 가중치 | D24: numeric | E24: 1 | F24: =VLOOKUP(A24,'2023년최신'!$A$2:$B$1000,2,FALSE) -> 건강설문·검진·영양조사 통합 가중치
A25: wt_oent | B25: 구강검사 & 영양조사 가중치 | D25: numeric | E25: 1 | F25: =VLOOKUP(A25,'2023년최신'!$A$2:$B$1000,2,FALSE) -> 구강검사·영양조사 가중치
A26: wt_biant | B26: 체성분검사 & 영양조사 가중치(10세이상) | D26: numeric | E26: 1 | F26: =VLOOKUP(A26,'2023년최신'!$A$2:$B$1000,2,FALSE) -> 체성분·영양조사 가중치(10세 이상)
A27: kstrata | B27: 분산추정 층 | D27: numeric | E27: 1 | F27: =VLOOKUP(A27,'2023년최신'!$A$2:$B$1000,2,FALSE) -> 분산추정 층
A28: cfam | B28: 가구원수 | C28: 1 : 1명 | 2 : 2명 | 3 : 3명 | 4 : 4명 | 5 : 5명 | 6 : 6명 이상 | 9 : 모름, 무응답 | | D28: category | E28: 0 | F28: =VLOOKUP(A28,'2023년최신'!$A$2:$B$1000,2,FALSE) -> 가구원수
A29: genertn | B29: 가구 세대구성코드 | C29: 1 : 1세대 가구 - 1인가구 | 2 : 1세대 가구 - 부부 | 3 : 1세대 가구 - 기타 | 4 : 2세대 가구 - 부부+미혼자녀 | 5 : 2세대 가구 ? 편부모+미혼자녀 | 6 : 2세대 가구 ? 기타 | 7 : 3세대 이상 가구 | 9 : 모름, 무응답 | | D29: category | E29: 0 | F29: =VLOOKUP(A29,'2023년최신'!$A$2:$B$1000,2,FALSE) -> 가구 세대구성코드
A30: allownc | B30: 기초생활수급 여부 | C30: 10 : 수급경험 있음(과거 또는 현재) | 20 : 수급경험 없음 | 99 : 모름, 무응답 | | D30: category | E30: 0 | F30: =VLOOKUP(A30,'2023년최신'!$A$2:$B$1000,2,FALSE) -> 기초생활수급 여부
A31: house | B31: 주택소유여부 | C31: 1 : 아니오 | 2 : 1채 있음 | 3 : 2채 이상 있음 | 9 : 모름, 무응답 | | D31: category | E31: 0 | F31: =VLOOKUP(A31,'2023년최신'!$A$2:$B$1000,2,FALSE) -> 주택소유여부
A32: live_t | B32: 주택형태 | C32: 1 : 단독주택 | 2 : 아파트 | 3 : 연립주택 | 4 : 다세대 주택 | 5 : 기타 | 9 : 모름, 무응답 | | D32: category | E32: 0 | F32: =VLOOKUP(A32,'2023년최신'!$A$2:$B$1000,2,FALSE) -> 주택형태
A33: ainc_unit1 | B33: 가구총소득(개방형): 소득단위 | C33: 1 : 연 | 2 : 월 | 8 : 비해당(선택형소득 응답) | 9 : 모름, 무응답 | | D33: category | E33: 0 | F33: =VLOOKUP(A33,'2023년최신'!$A$2:$B$1000,2,FALSE) -> 가구총소득 단위(개방형)
A34: ainc_1 | B34: 가구총소득(개방형): 소득액 | C34: 200 : 연 200만원 이하 | 200초과 ~ 18000미만 : (연속형 소득금액) | 18000 : 연 1억8천만원이상 | 17 : 월 약17만원 이하 | 17초과 ~ 1500미만 : (연속형 소득금액) | 1500 : 월 1,500만원 이상 | 999999 : 모름, 무응답 | | D34: numeric | E34: 0 | F34: =VLOOKUP(A34,'2023년최신'!$A$2:$B$1000,2,FALSE) -> 가구총소득 금액(개방형)
A35: ainc | B35: 월평균 가구총소득 | C35: 17 : 월 17만원 이하 | 17초과 ~ 1500미만 : (연속형 소득금액) | 1500 : 월 1,500만원 이상 | | D35: numeric | E35: 0 | F35: =VLOOKUP(A35,'2023년최신'!$A$2:$B$1000,2,FALSE) -> 월평균 가구총소득
A36: marri_1 | B36: 결혼여부 | C36: 1 : 기혼 | 2 : 미혼 | 9 : 모름, 무응답 | | D36: category | E36: 0 | F36: =VLOOKUP(A36,'2023년최신'!$A$2:$B$1000,2,FALSE) -> 결혼여부
A37: marri_2 | B37: 결혼상태 | C37: 1 : 유배우자, 동거 | 2 : 유배우자, 별거 | 3 : 사별 | 4 : 이혼 | 8 : 응답거부 | 9 : 모름 | 88 : 비해당(문항10-E) | 99 : 무응답 | | D37: category | E37: 0 | F37: =VLOOKUP(A37,'2023년최신'!$A$2:$B$1000,2,FALSE) -> 결혼상태
A38: fam_rela | B38: 가구주와의 관계 | C38: 1 : 본인 | 2 : 배우자 | 3 : 자녀 | 4 : 자녀배우자 | 5 : 손자녀 | 6 : 부모 | 7:조부모 | 8:형제자매|9:기타친척|10:비혈연 | 99 : 모름/무응답 | D38: category | E38: 0 | F38: =VLOOKUP(A38,'2023년최신'!$A$2:$B$1000,2,FALSE) -> 가구주와의 관계
A39: tins | B39: 건강보험종류 | C39: 10 : 국민건강보험(지역) | 20 : 국민건강보험(직장) | 30 : 의료급여 | 99 : 미가입, 모름, 무응답 | | D39: category | E39: 0 | F39: =VLOOKUP(A39,'2023년최신'!$A$2:$B$1000,2,FALSE) -> 건강보험 종류
A40: npins | B40: 민간의료보험 가입여부 | C40: 1 : 예 | 2 : 아니오 | 9 : 모름 | 99 : 무응답 | | D40: category | E40: 0 | F40: =VLOOKUP(A40,'2023년최신'!$A$2:$B$1000,2,FALSE) -> 민간의료보험 가입여부
...

Sheet 2022년변수
A1: mod_d
A2: ID
A3: ID_fam
A4: year
A5: region
A6: town_t
A7: apt_t
A8: psu
A9: sex
A10: age
A11: age_month
A12: incm
... A623: N_DUSUAL
